Watching for file changes with StatReloader
/home/centos/django/lib/python3.9/site-packages/pandas/compat/__init__.py:97: UserWarning: Could not import the lzma module. Your installed Python is incomplete. Attempting to use lzma compression will result in a RuntimeError.
  warnings.warn(msg)
System check identified some issues:

WARNINGS:
bearer.Bearer_In: (models.W042) Auto-created primary key used when not defining a primary key type, by default 'django.db.models.AutoField'.
	HINT: Configure the DEFAULT_AUTO_FIELD setting or the BearerConfig.default_auto_field attribute to point to a subclass of AutoField, e.g. 'django.db.models.BigAutoField'.
bearer.Bearer_Out: (models.W042) Auto-created primary key used when not defining a primary key type, by default 'django.db.models.AutoField'.
	HINT: Configure the DEFAULT_AUTO_FIELD setting or the BearerConfig.default_auto_field attribute to point to a subclass of AutoField, e.g. 'django.db.models.BigAutoField'.
corsheaders.CorsModel: (models.W042) Auto-created primary key used when not defining a primary key type, by default 'django.db.models.AutoField'.
	HINT: Configure the DEFAULT_AUTO_FIELD setting or the CorsHeadersAppConfig.default_auto_field attribute to point to a subclass of AutoField, e.g. 'django.db.models.BigAutoField'.
globalP.Countries: (models.W042) Auto-created primary key used when not defining a primary key type, by default 'django.db.models.AutoField'.
	HINT: Configure the DEFAULT_AUTO_FIELD setting or the GlobalpConfig.default_auto_field attribute to point to a subclass of AutoField, e.g. 'django.db.models.BigAutoField'.
globalP.Params: (models.W042) Auto-created primary key used when not defining a primary key type, by default 'django.db.models.AutoField'.
	HINT: Configure the DEFAULT_AUTO_FIELD setting or the GlobalpConfig.default_auto_field attribute to point to a subclass of AutoField, e.g. 'django.db.models.BigAutoField'.
pdp.Pdp_IN: (models.W042) Auto-created primary key used when not defining a primary key type, by default 'django.db.models.AutoField'.
	HINT: Configure the DEFAULT_AUTO_FIELD setting or the PdpConfig.default_auto_field attribute to point to a subclass of AutoField, e.g. 'django.db.models.BigAutoField'.
pdp.Pdp_OUT: (models.W042) Auto-created primary key used when not defining a primary key type, by default 'django.db.models.AutoField'.
	HINT: Configure the DEFAULT_AUTO_FIELD setting or the PdpConfig.default_auto_field attribute to point to a subclass of AutoField, e.g. 'django.db.models.BigAutoField'.
sai.Sai_IN: (models.W042) Auto-created primary key used when not defining a primary key type, by default 'django.db.models.AutoField'.
	HINT: Configure the DEFAULT_AUTO_FIELD setting or the SaiConfig.default_auto_field attribute to point to a subclass of AutoField, e.g. 'django.db.models.BigAutoField'.
sai.Sai_OUT: (models.W042) Auto-created primary key used when not defining a primary key type, by default 'django.db.models.AutoField'.
	HINT: Configure the DEFAULT_AUTO_FIELD setting or the SaiConfig.default_auto_field attribute to point to a subclass of AutoField, e.g. 'django.db.models.BigAutoField'.
uploadFile.File: (models.W042) Auto-created primary key used when not defining a primary key type, by default 'django.db.models.AutoField'.
	HINT: Configure the DEFAULT_AUTO_FIELD setting or the UploadFileConfig.default_auto_field attribute to point to a subclass of AutoField, e.g. 'django.db.models.BigAutoField'.

System check identified 10 issues (0 silenced).
[31/May/2021 09:35:45] "GET / HTTP/1.1" 200 5699
[31/May/2021 09:35:45] "GET /static/rest_framework/css/bootstrap-tweaks.css HTTP/1.1" 304 0
[31/May/2021 09:35:45] "GET /static/rest_framework/css/bootstrap.min.css HTTP/1.1" 200 121457
[31/May/2021 09:35:45] "GET /static/rest_framework/css/prettify.css HTTP/1.1" 304 0
[31/May/2021 09:35:45] "GET /static/rest_framework/css/default.css HTTP/1.1" 304 0
[31/May/2021 09:35:45] "GET /static/rest_framework/js/ajax-form.js HTTP/1.1" 304 0
[31/May/2021 09:35:45] "GET /static/rest_framework/js/jquery-3.5.1.min.js HTTP/1.1" 200 89476
[31/May/2021 09:35:45] "GET /static/rest_framework/js/csrf.js HTTP/1.1" 304 0
[31/May/2021 09:35:45] "GET /static/rest_framework/js/default.js HTTP/1.1" 304 0
[31/May/2021 09:35:45] "GET /static/rest_framework/js/bootstrap.min.js HTTP/1.1" 200 39680
[31/May/2021 09:35:45] "GET /static/rest_framework/js/prettify-min.js HTTP/1.1" 304 0
[31/May/2021 09:35:46] "GET /static/rest_framework/img/grid.png HTTP/1.1" 304 0
/home/centos/django/lib/python3.9/site-packages/rest_framework/pagination.py:200: UnorderedObjectListWarning: Pagination may yield inconsistent results with an unordered object_list: <class 'bearer.models.Bearer_Out'> QuerySet.
  paginator = self.django_paginator_class(queryset, page_size)
[31/May/2021 09:35:48] "GET /bearer/ HTTP/1.1" 200 11552
/home/centos/django/lib/python3.9/site-packages/rest_framework/pagination.py:200: UnorderedObjectListWarning: Pagination may yield inconsistent results with an unordered object_list: <class 'pdp.models.Pdp_IN'> QuerySet.
  paginator = self.django_paginator_class(queryset, page_size)
[31/May/2021 09:35:57] "GET /pdp/ HTTP/1.1" 200 11233
[31/May/2021 09:37:38] "GET /bearer/ HTTP/1.1" 200 11552
/home/centos/django/lib/python3.9/site-packages/rest_framework/pagination.py:200: UnorderedObjectListWarning: Pagination may yield inconsistent results with an unordered object_list: <class 'sai.models.Sai_OUT'> QuerySet.
  paginator = self.django_paginator_class(queryset, page_size)
[31/May/2021 09:37:42] "GET /sai/ HTTP/1.1" 200 25011
[31/May/2021 09:38:08] "GET /sai/1/ HTTP/1.1" 200 12717
[31/May/2021 09:38:26] "PUT /sai/1/ HTTP/1.1" 200 12717
[31/May/2021 09:54:41] "GET /sai/ HTTP/1.1" 200 25011
[31/May/2021 10:03:54] "GET /sai/ HTTP/1.1" 200 25239
Method Not Allowed: /sai/upload/
[31/May/2021 10:03:59] "GET /sai/upload/ HTTP/1.1" 405 8685
[31/May/2021 10:04:13] "POST /sai/upload/ HTTP/1.1" 201 8946
[31/May/2021 10:04:31] "POST /sai/upload/ HTTP/1.1" 201 8946
/home/centos/django/lib/python3.9/site-packages/rest_framework/pagination.py:200: UnorderedObjectListWarning: Pagination may yield inconsistent results with an unordered object_list: <class 'sai.models.Sai_OUT'> QuerySet.
  paginator = self.django_paginator_class(queryset, page_size)
[31/May/2021 10:04:36] "GET /sai/ HTTP/1.1" 200 25594
Method Not Allowed: /sai/parametre/
[31/May/2021 10:04:50] "GET /sai/parametre/ HTTP/1.1" 405 9275
[31/May/2021 10:04:57] "GET /sai/ HTTP/1.1" 200 25594
Internal Server Error: /sai/parametre/
Traceback (most recent call last):
  File "/home/centos/django/lib/python3.9/site-packages/django/core/handlers/exception.py", line 47, in inner
    response = get_response(request)
  File "/home/centos/django/lib/python3.9/site-packages/django/core/handlers/base.py", line 181, in _get_response
    response = wrapped_callback(request, *callback_args, **callback_kwargs)
  File "/home/centos/django/lib/python3.9/site-packages/django/views/decorators/csrf.py", line 54, in wrapped_view
    return view_func(*args, **kwargs)
  File "/home/centos/django/lib/python3.9/site-packages/rest_framework/viewsets.py", line 125, in view
    return self.dispatch(request, *args, **kwargs)
  File "/home/centos/django/lib/python3.9/site-packages/rest_framework/views.py", line 509, in dispatch
    response = self.handle_exception(exc)
  File "/home/centos/django/lib/python3.9/site-packages/rest_framework/views.py", line 469, in handle_exception
    self.raise_uncaught_exception(exc)
  File "/home/centos/django/lib/python3.9/site-packages/rest_framework/views.py", line 480, in raise_uncaught_exception
    raise exc
  File "/home/centos/django/lib/python3.9/site-packages/rest_framework/views.py", line 506, in dispatch
    response = handler(request, *args, **kwargs)
  File "/home/centos/test/back/sai/views.py", line 82, in parametre
    debut_obj = getDateToMills(serializer.validated_data['dateDebut'])
  File "/home/centos/test/back/sai/views.py", line 163, in getDateToMills
    date_time_obj = datetime.strptime(date, '%b %d, %Y')
  File "/usr/local/lib/python3.9/_strptime.py", line 568, in _strptime_datetime
    tt, fraction, gmtoff_fraction = _strptime(data_string, format)
  File "/usr/local/lib/python3.9/_strptime.py", line 352, in _strptime
    raise ValueError("unconverted data remains: %s" %
ValueError: unconverted data remains:  08:00
[31/May/2021 10:05:25] "POST /sai/parametre/ HTTP/1.1" 500 107699
Internal Server Error: /sai/parametre/
Traceback (most recent call last):
  File "/home/centos/django/lib/python3.9/site-packages/django/core/handlers/exception.py", line 47, in inner
    response = get_response(request)
  File "/home/centos/django/lib/python3.9/site-packages/django/core/handlers/base.py", line 181, in _get_response
    response = wrapped_callback(request, *callback_args, **callback_kwargs)
  File "/home/centos/django/lib/python3.9/site-packages/django/views/decorators/csrf.py", line 54, in wrapped_view
    return view_func(*args, **kwargs)
  File "/home/centos/django/lib/python3.9/site-packages/rest_framework/viewsets.py", line 125, in view
    return self.dispatch(request, *args, **kwargs)
  File "/home/centos/django/lib/python3.9/site-packages/rest_framework/views.py", line 509, in dispatch
    response = self.handle_exception(exc)
  File "/home/centos/django/lib/python3.9/site-packages/rest_framework/views.py", line 469, in handle_exception
    self.raise_uncaught_exception(exc)
  File "/home/centos/django/lib/python3.9/site-packages/rest_framework/views.py", line 480, in raise_uncaught_exception
    raise exc
  File "/home/centos/django/lib/python3.9/site-packages/rest_framework/views.py", line 506, in dispatch
    response = handler(request, *args, **kwargs)
  File "/home/centos/test/back/sai/views.py", line 102, in parametre
    return Response(razbi.data, status=status.HTTP_201_CREATED)
  File "/home/centos/django/lib/python3.9/site-packages/rest_framework/serializers.py", line 745, in data
    ret = super().data
  File "/home/centos/django/lib/python3.9/site-packages/rest_framework/serializers.py", line 246, in data
    self._data = self.to_representation(self.instance)
  File "/home/centos/django/lib/python3.9/site-packages/rest_framework/serializers.py", line 663, in to_representation
    return [
  File "/home/centos/django/lib/python3.9/site-packages/django/db/models/query.py", line 1484, in __iter__
    self._fetch_all()
  File "/home/centos/django/lib/python3.9/site-packages/django/db/models/query.py", line 1471, in _fetch_all
    self._result_cache = list(self.iterator())
  File "/home/centos/django/lib/python3.9/site-packages/django/db/models/query.py", line 1499, in iterator
    raise exceptions.FieldDoesNotExist(
django.core.exceptions.FieldDoesNotExist: Raw query must include the primary key
[31/May/2021 10:05:36] "POST /sai/parametre/ HTTP/1.1" 500 123570
Internal Server Error: /sai/parametre/
Traceback (most recent call last):
  File "/home/centos/django/lib/python3.9/site-packages/django/core/handlers/exception.py", line 47, in inner
    response = get_response(request)
  File "/home/centos/django/lib/python3.9/site-packages/django/core/handlers/base.py", line 181, in _get_response
    response = wrapped_callback(request, *callback_args, **callback_kwargs)
  File "/home/centos/django/lib/python3.9/site-packages/django/views/decorators/csrf.py", line 54, in wrapped_view
    return view_func(*args, **kwargs)
  File "/home/centos/django/lib/python3.9/site-packages/rest_framework/viewsets.py", line 125, in view
    return self.dispatch(request, *args, **kwargs)
  File "/home/centos/django/lib/python3.9/site-packages/rest_framework/views.py", line 509, in dispatch
    response = self.handle_exception(exc)
  File "/home/centos/django/lib/python3.9/site-packages/rest_framework/views.py", line 469, in handle_exception
    self.raise_uncaught_exception(exc)
  File "/home/centos/django/lib/python3.9/site-packages/rest_framework/views.py", line 480, in raise_uncaught_exception
    raise exc
  File "/home/centos/django/lib/python3.9/site-packages/rest_framework/views.py", line 506, in dispatch
    response = handler(request, *args, **kwargs)
  File "/home/centos/test/back/sai/views.py", line 82, in parametre
    debut_obj = getDateToMills(serializer.validated_data['dateDebut'])
  File "/home/centos/test/back/sai/views.py", line 163, in getDateToMills
    date_time_obj = datetime.strptime(date, '%b %d, %Y')
  File "/usr/local/lib/python3.9/_strptime.py", line 568, in _strptime_datetime
    tt, fraction, gmtoff_fraction = _strptime(data_string, format)
  File "/usr/local/lib/python3.9/_strptime.py", line 349, in _strptime
    raise ValueError("time data %r does not match format %r" %
ValueError: time data '1606204800' does not match format '%b %d, %Y'
[31/May/2021 10:05:54] "POST /sai/parametre/ HTTP/1.1" 500 107956
[31/May/2021 10:06:25] "GET /ping/ HTTP/1.1" 201 5315
[31/May/2021 10:12:57] "GET /ping/ HTTP/1.1" 201 16
Method Not Allowed: /sai/parametre/
[31/May/2021 10:52:06] "GET /sai/parametre/ HTTP/1.1" 405 9275
[31/May/2021 10:52:09] "GET /sai/ HTTP/1.1" 200 25594
Method Not Allowed: /sai/parametre/
[31/May/2021 10:52:13] "GET /sai/parametre/ HTTP/1.1" 405 9275
Internal Server Error: /sai/parametre/
Traceback (most recent call last):
  File "/home/centos/django/lib/python3.9/site-packages/django/core/handlers/exception.py", line 47, in inner
    response = get_response(request)
  File "/home/centos/django/lib/python3.9/site-packages/django/core/handlers/base.py", line 181, in _get_response
    response = wrapped_callback(request, *callback_args, **callback_kwargs)
  File "/home/centos/django/lib/python3.9/site-packages/django/views/decorators/csrf.py", line 54, in wrapped_view
    return view_func(*args, **kwargs)
  File "/home/centos/django/lib/python3.9/site-packages/rest_framework/viewsets.py", line 125, in view
    return self.dispatch(request, *args, **kwargs)
  File "/home/centos/django/lib/python3.9/site-packages/rest_framework/views.py", line 509, in dispatch
    response = self.handle_exception(exc)
  File "/home/centos/django/lib/python3.9/site-packages/rest_framework/views.py", line 469, in handle_exception
    self.raise_uncaught_exception(exc)
  File "/home/centos/django/lib/python3.9/site-packages/rest_framework/views.py", line 480, in raise_uncaught_exception
    raise exc
  File "/home/centos/django/lib/python3.9/site-packages/rest_framework/views.py", line 506, in dispatch
    response = handler(request, *args, **kwargs)
  File "/home/centos/test/back/sai/views.py", line 82, in parametre
    debut_obj = getDateToMills(serializer.validated_data['dateDebut'])
  File "/home/centos/test/back/sai/views.py", line 163, in getDateToMills
    date_time_obj = datetime.strptime(date, '%b %d, %Y')
  File "/usr/local/lib/python3.9/_strptime.py", line 568, in _strptime_datetime
    tt, fraction, gmtoff_fraction = _strptime(data_string, format)
  File "/usr/local/lib/python3.9/_strptime.py", line 352, in _strptime
    raise ValueError("unconverted data remains: %s" %
ValueError: unconverted data remains:  08:00
[31/May/2021 10:52:27] "POST /sai/parametre/ HTTP/1.1" 500 107699
Internal Server Error: /sai/parametre/
Traceback (most recent call last):
  File "/home/centos/django/lib/python3.9/site-packages/django/core/handlers/exception.py", line 47, in inner
    response = get_response(request)
  File "/home/centos/django/lib/python3.9/site-packages/django/core/handlers/base.py", line 181, in _get_response
    response = wrapped_callback(request, *callback_args, **callback_kwargs)
  File "/home/centos/django/lib/python3.9/site-packages/django/views/decorators/csrf.py", line 54, in wrapped_view
    return view_func(*args, **kwargs)
  File "/home/centos/django/lib/python3.9/site-packages/rest_framework/viewsets.py", line 125, in view
    return self.dispatch(request, *args, **kwargs)
  File "/home/centos/django/lib/python3.9/site-packages/rest_framework/views.py", line 509, in dispatch
    response = self.handle_exception(exc)
  File "/home/centos/django/lib/python3.9/site-packages/rest_framework/views.py", line 469, in handle_exception
    self.raise_uncaught_exception(exc)
  File "/home/centos/django/lib/python3.9/site-packages/rest_framework/views.py", line 480, in raise_uncaught_exception
    raise exc
  File "/home/centos/django/lib/python3.9/site-packages/rest_framework/views.py", line 506, in dispatch
    response = handler(request, *args, **kwargs)
  File "/home/centos/test/back/sai/views.py", line 102, in parametre
    return Response(razbi.data, status=status.HTTP_201_CREATED)
  File "/home/centos/django/lib/python3.9/site-packages/rest_framework/serializers.py", line 745, in data
    ret = super().data
  File "/home/centos/django/lib/python3.9/site-packages/rest_framework/serializers.py", line 246, in data
    self._data = self.to_representation(self.instance)
  File "/home/centos/django/lib/python3.9/site-packages/rest_framework/serializers.py", line 663, in to_representation
    return [
  File "/home/centos/django/lib/python3.9/site-packages/django/db/models/query.py", line 1484, in __iter__
    self._fetch_all()
  File "/home/centos/django/lib/python3.9/site-packages/django/db/models/query.py", line 1471, in _fetch_all
    self._result_cache = list(self.iterator())
  File "/home/centos/django/lib/python3.9/site-packages/django/db/models/query.py", line 1499, in iterator
    raise exceptions.FieldDoesNotExist(
django.core.exceptions.FieldDoesNotExist: Raw query must include the primary key
[31/May/2021 10:52:38] "POST /sai/parametre/ HTTP/1.1" 500 123570
Internal Server Error: /sai/parametre/
Traceback (most recent call last):
  File "/home/centos/django/lib/python3.9/site-packages/django/core/handlers/exception.py", line 47, in inner
    response = get_response(request)
  File "/home/centos/django/lib/python3.9/site-packages/django/core/handlers/base.py", line 181, in _get_response
    response = wrapped_callback(request, *callback_args, **callback_kwargs)
  File "/home/centos/django/lib/python3.9/site-packages/django/views/decorators/csrf.py", line 54, in wrapped_view
    return view_func(*args, **kwargs)
  File "/home/centos/django/lib/python3.9/site-packages/rest_framework/viewsets.py", line 125, in view
    return self.dispatch(request, *args, **kwargs)
  File "/home/centos/django/lib/python3.9/site-packages/rest_framework/views.py", line 509, in dispatch
    response = self.handle_exception(exc)
  File "/home/centos/django/lib/python3.9/site-packages/rest_framework/views.py", line 469, in handle_exception
    self.raise_uncaught_exception(exc)
  File "/home/centos/django/lib/python3.9/site-packages/rest_framework/views.py", line 480, in raise_uncaught_exception
    raise exc
  File "/home/centos/django/lib/python3.9/site-packages/rest_framework/views.py", line 506, in dispatch
    response = handler(request, *args, **kwargs)
  File "/home/centos/test/back/sai/views.py", line 82, in parametre
    debut_obj = getDateToMills(serializer.validated_data['dateDebut'])
  File "/home/centos/test/back/sai/views.py", line 163, in getDateToMills
    date_time_obj = datetime.strptime(date, '%b %d, %Y')
  File "/usr/local/lib/python3.9/_strptime.py", line 568, in _strptime_datetime
    tt, fraction, gmtoff_fraction = _strptime(data_string, format)
  File "/usr/local/lib/python3.9/_strptime.py", line 349, in _strptime
    raise ValueError("time data %r does not match format %r" %
ValueError: time data '1606208400.0' does not match format '%b %d, %Y'
[31/May/2021 10:52:53] "POST /sai/parametre/ HTTP/1.1" 500 107982
Internal Server Error: /sai/parametre/
Traceback (most recent call last):
  File "/home/centos/django/lib/python3.9/site-packages/django/core/handlers/exception.py", line 47, in inner
    response = get_response(request)
  File "/home/centos/django/lib/python3.9/site-packages/django/core/handlers/base.py", line 181, in _get_response
    response = wrapped_callback(request, *callback_args, **callback_kwargs)
  File "/home/centos/django/lib/python3.9/site-packages/django/views/decorators/csrf.py", line 54, in wrapped_view
    return view_func(*args, **kwargs)
  File "/home/centos/django/lib/python3.9/site-packages/rest_framework/viewsets.py", line 125, in view
    return self.dispatch(request, *args, **kwargs)
  File "/home/centos/django/lib/python3.9/site-packages/rest_framework/views.py", line 509, in dispatch
    response = self.handle_exception(exc)
  File "/home/centos/django/lib/python3.9/site-packages/rest_framework/views.py", line 469, in handle_exception
    self.raise_uncaught_exception(exc)
  File "/home/centos/django/lib/python3.9/site-packages/rest_framework/views.py", line 480, in raise_uncaught_exception
    raise exc
  File "/home/centos/django/lib/python3.9/site-packages/rest_framework/views.py", line 506, in dispatch
    response = handler(request, *args, **kwargs)
  File "/home/centos/test/back/sai/views.py", line 82, in parametre
    debut_obj = getDateToMills(serializer.validated_data['dateDebut'])
  File "/home/centos/test/back/sai/views.py", line 163, in getDateToMills
    date_time_obj = datetime.strptime(date, '%b %d, %Y')
  File "/usr/local/lib/python3.9/_strptime.py", line 568, in _strptime_datetime
    tt, fraction, gmtoff_fraction = _strptime(data_string, format)
  File "/usr/local/lib/python3.9/_strptime.py", line 349, in _strptime
    raise ValueError("time data %r does not match format %r" %
ValueError: time data '8' does not match format '%b %d, %Y'
[31/May/2021 10:53:07] "POST /sai/parametre/ HTTP/1.1" 500 107839
Internal Server Error: /sai/parametre/
Traceback (most recent call last):
  File "/home/centos/django/lib/python3.9/site-packages/django/core/handlers/exception.py", line 47, in inner
    response = get_response(request)
  File "/home/centos/django/lib/python3.9/site-packages/django/core/handlers/base.py", line 181, in _get_response
    response = wrapped_callback(request, *callback_args, **callback_kwargs)
  File "/home/centos/django/lib/python3.9/site-packages/django/views/decorators/csrf.py", line 54, in wrapped_view
    return view_func(*args, **kwargs)
  File "/home/centos/django/lib/python3.9/site-packages/rest_framework/viewsets.py", line 125, in view
    return self.dispatch(request, *args, **kwargs)
  File "/home/centos/django/lib/python3.9/site-packages/rest_framework/views.py", line 509, in dispatch
    response = self.handle_exception(exc)
  File "/home/centos/django/lib/python3.9/site-packages/rest_framework/views.py", line 469, in handle_exception
    self.raise_uncaught_exception(exc)
  File "/home/centos/django/lib/python3.9/site-packages/rest_framework/views.py", line 480, in raise_uncaught_exception
    raise exc
  File "/home/centos/django/lib/python3.9/site-packages/rest_framework/views.py", line 506, in dispatch
    response = handler(request, *args, **kwargs)
  File "/home/centos/test/back/sai/views.py", line 102, in parametre
    return Response(razbi.data, status=status.HTTP_201_CREATED)
  File "/home/centos/django/lib/python3.9/site-packages/rest_framework/serializers.py", line 745, in data
    ret = super().data
  File "/home/centos/django/lib/python3.9/site-packages/rest_framework/serializers.py", line 246, in data
    self._data = self.to_representation(self.instance)
  File "/home/centos/django/lib/python3.9/site-packages/rest_framework/serializers.py", line 663, in to_representation
    return [
  File "/home/centos/django/lib/python3.9/site-packages/django/db/models/query.py", line 1484, in __iter__
    self._fetch_all()
  File "/home/centos/django/lib/python3.9/site-packages/django/db/models/query.py", line 1471, in _fetch_all
    self._result_cache = list(self.iterator())
  File "/home/centos/django/lib/python3.9/site-packages/django/db/models/query.py", line 1499, in iterator
    raise exceptions.FieldDoesNotExist(
django.core.exceptions.FieldDoesNotExist: Raw query must include the primary key
[31/May/2021 10:53:33] "POST /sai/parametre/ HTTP/1.1" 500 123570
[31/May/2021 11:13:58] code 400, message Bad HTTP/0.9 request type ('\x03\x00\x00/*à\x00\x00\x00\x00\x00Cookie:')
[31/May/2021 11:13:58] "  /*à     Cookie: mstshash=Administr" 400 -
[31/May/2021 11:22:02] "GET / HTTP/1.1" 200 5699
Not Found: /favicon.ico
[31/May/2021 11:22:03] "GET /favicon.ico HTTP/1.1" 404 9744
[31/May/2021 11:22:05] "GET /sai/ HTTP/1.1" 200 25366
Method Not Allowed: /sai/parametre/
[31/May/2021 11:22:11] "GET /sai/parametre/ HTTP/1.1" 405 9047
[31/May/2021 11:22:25] "GET /sai/ HTTP/1.1" 200 25366
[31/May/2021 11:22:33] "GET /sai/?page=12 HTTP/1.1" 200 21021
[31/May/2021 11:22:57] "GET /sai/?page=10 HTTP/1.1" 200 25672
[31/May/2021 11:22:59] "GET /sai/?page=9 HTTP/1.1" 200 25773
[31/May/2021 11:23:01] "GET /sai/?page=8 HTTP/1.1" 200 25752
[31/May/2021 11:23:03] "GET /sai/?page=7 HTTP/1.1" 200 25763
[31/May/2021 11:23:05] "GET /sai/?page=6 HTTP/1.1" 200 25741
[31/May/2021 11:23:07] "GET /sai/?page=5 HTTP/1.1" 200 25742
[31/May/2021 11:23:09] "GET /sai/?page=4 HTTP/1.1" 200 25739
[31/May/2021 11:23:11] "GET /sai/?page=3 HTTP/1.1" 200 25716
[31/May/2021 11:23:13] "GET /sai/ HTTP/1.1" 200 25366
Method Not Allowed: /sai/parametre/
[31/May/2021 11:23:21] "GET /sai/parametre/ HTTP/1.1" 405 9047
Internal Server Error: /sai/parametre/
Traceback (most recent call last):
  File "/home/centos/django/lib/python3.9/site-packages/django/core/handlers/exception.py", line 47, in inner
    response = get_response(request)
  File "/home/centos/django/lib/python3.9/site-packages/django/core/handlers/base.py", line 181, in _get_response
    response = wrapped_callback(request, *callback_args, **callback_kwargs)
  File "/home/centos/django/lib/python3.9/site-packages/django/views/decorators/csrf.py", line 54, in wrapped_view
    return view_func(*args, **kwargs)
  File "/home/centos/django/lib/python3.9/site-packages/rest_framework/viewsets.py", line 125, in view
    return self.dispatch(request, *args, **kwargs)
  File "/home/centos/django/lib/python3.9/site-packages/rest_framework/views.py", line 509, in dispatch
    response = self.handle_exception(exc)
  File "/home/centos/django/lib/python3.9/site-packages/rest_framework/views.py", line 469, in handle_exception
    self.raise_uncaught_exception(exc)
  File "/home/centos/django/lib/python3.9/site-packages/rest_framework/views.py", line 480, in raise_uncaught_exception
    raise exc
  File "/home/centos/django/lib/python3.9/site-packages/rest_framework/views.py", line 506, in dispatch
    response = handler(request, *args, **kwargs)
  File "/home/centos/test/back/sai/views.py", line 102, in parametre
    return Response(razbi.data, status=status.HTTP_201_CREATED)
  File "/home/centos/django/lib/python3.9/site-packages/rest_framework/serializers.py", line 745, in data
    ret = super().data
  File "/home/centos/django/lib/python3.9/site-packages/rest_framework/serializers.py", line 246, in data
    self._data = self.to_representation(self.instance)
  File "/home/centos/django/lib/python3.9/site-packages/rest_framework/serializers.py", line 663, in to_representation
    return [
  File "/home/centos/django/lib/python3.9/site-packages/django/db/models/query.py", line 1484, in __iter__
    self._fetch_all()
  File "/home/centos/django/lib/python3.9/site-packages/django/db/models/query.py", line 1471, in _fetch_all
    self._result_cache = list(self.iterator())
  File "/home/centos/django/lib/python3.9/site-packages/django/db/models/query.py", line 1499, in iterator
    raise exceptions.FieldDoesNotExist(
django.core.exceptions.FieldDoesNotExist: Raw query must include the primary key
[31/May/2021 11:23:39] "POST /sai/parametre/ HTTP/1.1" 500 123383
/home/centos/test/back/bearer/views.py changed, reloading.
Performing system checks...

May 31, 2021 - 09:27:37
Django version 3.2.3, using settings 'back.settings'
Starting development server at http://0.0.0.0:8095/
Quit the server with CONTROL-C.
<QueryDict: {'csrfmiddlewaretoken': ['jPLgcMqBNXlHsbjwhIX9nmLXlzQw2JSig7DGdAk0VFxzVOxSh2etKldlpdxaMTn8'], 'bound': ['out'], 'file': [<InMemoryUploadedFile: DAILY_SAI_OUT_15-02-2021.xlsx (application/vnd.openxmlformats-officedocument.spreadsheetml.sheet)>]}>
             Date            PLMN Carrier  ... Failed Transactions      Eff 
0    FEB 15, 2021  1_Canada Bell Mobility  ...                   0  1.000000
1    FEB 15, 2021         1_Canada Rogers  ...                  11  0.999902
2    FEB 15, 2021          1_Canada Telus  ...                   1  0.996047
3    FEB 15, 2021    1_USA ATT W Cingular  ...                   5  0.999981
4    FEB 15, 2021            1_USA Others  ...                   0  1.000000
..            ...                     ...  ...                 ...       ...
207  FEB 15, 2021      972_Israel Cellcom  ...                   0  1.000000
208  FEB 15, 2021       972_Israel Orange  ...                   0  1.000000
209  FEB 15, 2021          974_Qatar Qtel  ...                   0  1.000000
210  FEB 15, 2021          98_Iran Mobile  ...                   0  1.000000
211  FEB 15, 2021                 UNKNOWN  ...                   0  1.000000

[212 rows x 9 columns]
<QueryDict: {'csrfmiddlewaretoken': ['DkDxyup4Kn1V2FW40eFQBspUBUtHjPc6ACvXzijtS5dNviaq0yWaYrRiFyal3ZHW'], 'bound': ['in'], 'file': [<InMemoryUploadedFile: DAILY_SAI_IN_15-02-2021.xlsx (application/vnd.openxmlformats-officedocument.spreadsheetml.sheet)>]}>
              Date            PLMN Carrier  ... Failed Transactions       EFF
0     FEB 15, 2021  1_Canada Bell Mobility  ...                   0  1.000000
1     FEB 15, 2021  1_Canada Bell Mobility  ...                   0  1.000000
2     FEB 15, 2021  1_Canada Bell Mobility  ...                   0  1.000000
3     FEB 15, 2021  1_Canada Bell Mobility  ...                   0  1.000000
4     FEB 15, 2021           1_Canada Fido  ...                   2  0.977273
...            ...                     ...  ...                 ...       ...
1207  FEB 15, 2021                 UNKNOWN  ...                 294  0.289855
1208  FEB 15, 2021                 UNKNOWN  ...                   7  0.461538
1209  FEB 15, 2021                 UNKNOWN  ...                   4  0.333333
1210  FEB 15, 2021                 UNKNOWN  ...                 143  0.309179
1211  FEB 15, 2021                 UNKNOWN  ...               16191  0.822098

[1212 rows x 9 columns]
Watching for file changes with StatReloader
/home/centos/django/lib/python3.9/site-packages/pandas/compat/__init__.py:97: UserWarning: Could not import the lzma module. Your installed Python is incomplete. Attempting to use lzma compression will result in a RuntimeError.
  warnings.warn(msg)
System check identified some issues:

WARNINGS:
bearer.Bearer_In: (models.W042) Auto-created primary key used when not defining a primary key type, by default 'django.db.models.AutoField'.
	HINT: Configure the DEFAULT_AUTO_FIELD setting or the BearerConfig.default_auto_field attribute to point to a subclass of AutoField, e.g. 'django.db.models.BigAutoField'.
bearer.Bearer_Out: (models.W042) Auto-created primary key used when not defining a primary key type, by default 'django.db.models.AutoField'.
	HINT: Configure the DEFAULT_AUTO_FIELD setting or the BearerConfig.default_auto_field attribute to point to a subclass of AutoField, e.g. 'django.db.models.BigAutoField'.
corsheaders.CorsModel: (models.W042) Auto-created primary key used when not defining a primary key type, by default 'django.db.models.AutoField'.
	HINT: Configure the DEFAULT_AUTO_FIELD setting or the CorsHeadersAppConfig.default_auto_field attribute to point to a subclass of AutoField, e.g. 'django.db.models.BigAutoField'.
globalP.Countries: (models.W042) Auto-created primary key used when not defining a primary key type, by default 'django.db.models.AutoField'.
	HINT: Configure the DEFAULT_AUTO_FIELD setting or the GlobalpConfig.default_auto_field attribute to point to a subclass of AutoField, e.g. 'django.db.models.BigAutoField'.
globalP.Params: (models.W042) Auto-created primary key used when not defining a primary key type, by default 'django.db.models.AutoField'.
	HINT: Configure the DEFAULT_AUTO_FIELD setting or the GlobalpConfig.default_auto_field attribute to point to a subclass of AutoField, e.g. 'django.db.models.BigAutoField'.
pdp.Pdp_IN: (models.W042) Auto-created primary key used when not defining a primary key type, by default 'django.db.models.AutoField'.
	HINT: Configure the DEFAULT_AUTO_FIELD setting or the PdpConfig.default_auto_field attribute to point to a subclass of AutoField, e.g. 'django.db.models.BigAutoField'.
pdp.Pdp_OUT: (models.W042) Auto-created primary key used when not defining a primary key type, by default 'django.db.models.AutoField'.
	HINT: Configure the DEFAULT_AUTO_FIELD setting or the PdpConfig.default_auto_field attribute to point to a subclass of AutoField, e.g. 'django.db.models.BigAutoField'.
sai.Sai_IN: (models.W042) Auto-created primary key used when not defining a primary key type, by default 'django.db.models.AutoField'.
	HINT: Configure the DEFAULT_AUTO_FIELD setting or the SaiConfig.default_auto_field attribute to point to a subclass of AutoField, e.g. 'django.db.models.BigAutoField'.
sai.Sai_OUT: (models.W042) Auto-created primary key used when not defining a primary key type, by default 'django.db.models.AutoField'.
	HINT: Configure the DEFAULT_AUTO_FIELD setting or the SaiConfig.default_auto_field attribute to point to a subclass of AutoField, e.g. 'django.db.models.BigAutoField'.
uploadFile.File: (models.W042) Auto-created primary key used when not defining a primary key type, by default 'django.db.models.AutoField'.
	HINT: Configure the DEFAULT_AUTO_FIELD setting or the UploadFileConfig.default_auto_field attribute to point to a subclass of AutoField, e.g. 'django.db.models.BigAutoField'.

System check identified 10 issues (0 silenced).
